Traceback (most recent call last):
  File "/Users/olgascrivner/Documents/IU-DataScience/Time-Series/Spring2022/book/venv/lib/python3.10/site-packages/jupyter_cache/executors/utils.py", line 58, in single_nb_execution
    executenb(
  File "/Users/olgascrivner/Documents/IU-DataScience/Time-Series/Spring2022/book/venv/lib/python3.10/site-packages/nbclient/client.py", line 1314, in execute
    return NotebookClient(nb=nb, resources=resources, km=km, **kwargs).execute()
  File "/Users/olgascrivner/Documents/IU-DataScience/Time-Series/Spring2022/book/venv/lib/python3.10/site-packages/jupyter_core/utils/__init__.py", line 165, in wrapped
    return loop.run_until_complete(inner)
  File "/Library/Frameworks/Python.framework/Versions/3.10/lib/python3.10/asyncio/base_events.py", line 649, in run_until_complete
    return future.result()
  File "/Users/olgascrivner/Documents/IU-DataScience/Time-Series/Spring2022/book/venv/lib/python3.10/site-packages/nbclient/client.py", line 709, in async_execute
    await self.async_execute_cell(
  File "/Users/olgascrivner/Documents/IU-DataScience/Time-Series/Spring2022/book/venv/lib/python3.10/site-packages/nbclient/client.py", line 1062, in async_execute_cell
    await self._check_raise_for_error(cell, cell_index, exec_reply)
  File "/Users/olgascrivner/Documents/IU-DataScience/Time-Series/Spring2022/book/venv/lib/python3.10/site-packages/nbclient/client.py", line 918, in _check_raise_for_error
    raise CellExecutionError.from_cell_and_msg(cell, exec_reply_content)
nbclient.exceptions.CellExecutionError: An error occurred while executing the following cell:
------------------
import warnings
warnings.filterwarnings('ignore')
from pandas import read_csv
from pandas import datetime
from matplotlib import pyplot
from pandas.plotting import autocorrelation_plot
from statsmodels.tsa.arima.model import ARIMA
from pandas import DataFrame
from sklearn.metrics import mean_squared_error
from math import sqrt
------------------


[0;31m---------------------------------------------------------------------------[0m
[0;31mModuleNotFoundError[0m                       Traceback (most recent call last)
Cell [0;32mIn[1], line 3[0m
[1;32m      1[0m [38;5;28;01mimport[39;00m [38;5;21;01mwarnings[39;00m
[1;32m      2[0m warnings[38;5;241m.[39mfilterwarnings([38;5;124m'[39m[38;5;124mignore[39m[38;5;124m'[39m)
[0;32m----> 3[0m [38;5;28;01mfrom[39;00m [38;5;21;01mpandas[39;00m [38;5;28;01mimport[39;00m read_csv
[1;32m      4[0m [38;5;28;01mfrom[39;00m [38;5;21;01mpandas[39;00m [38;5;28;01mimport[39;00m datetime
[1;32m      5[0m [38;5;28;01mfrom[39;00m [38;5;21;01mmatplotlib[39;00m [38;5;28;01mimport[39;00m pyplot

[0;31mModuleNotFoundError[0m: No module named 'pandas'

